<?xml version="1.0" encoding="UTF-8"?><testsuite name="nosetests" tests="57" errors="14" failures="0" skip="1"><testcase classname="integration.test_api.AfterBuyIntegrationTests" name="test_brands" time="1.805"></testcase><testcase classname="integration.test_api.AfterBuyIntegrationTests" name="test_products" time="0.003"></testcase><testcase classname="integration.test_api.AfterBuyIntegrationTests" name="test_users" time="0.003"></testcase><testcase classname="integration.test_celery.CeleryTestCaseBase" name="test_delay_message" time="0.089"></testcase><testcase classname="integration.test_feeds.FeedsResourceTest" name="test_authentication" time="0.187"></testcase><testcase classname="integration.test_feeds.FeedsResourceTest" name="test_coupon_redamption_feed" time="0.446"></testcase><testcase classname="integration.test_feeds.FeedsResourceTest" name="test_coupon_status_on_dispatch_feed" time="0.000"><skipped type="unittest.case.SkipTest" message="Skipping Adding this functionality in future"><![CDATA[SkipTest: Skipping Adding this functionality in future
]]></skipped></testcase><testcase classname="integration.test_feeds.FeedsResourceTest" name="test_coupon_status_without_ucn" time="0.153"></testcase><testcase classname="integration.test_feeds.FeedsResourceTest" name="test_partial_fail" time="0.185"></testcase><testcase classname="integration.test_feeds.FeedsResourceTest" name="test_product_dispatch" time="0.275"></testcase><testcase classname="integration.test_feeds.FeedsResourceTest" name="test_product_purchase" time="0.088"></testcase><testcase classname="integration.test_feeds.FeedsResourceTest" name="test_service_advisor_dealer_relationship" time="0.345"></testcase><testcase classname="integration.test_feeds.FeedsResourceTest" name="test_service_advisor_feed" time="0.223"></testcase><testcase classname="integration.test_feeds.FeedsResourceTest" name="test_update_customer_number" time="0.258"></testcase><testcase classname="integration.test_home.TestHome" name="test_home" time="0.000"></testcase><testcase classname="integration.test_message.BrandData" name="test_get_all_brand" time="0.025"></testcase><testcase classname="integration.test_message.BrandData" name="test_get_all_products_of_a_brand" time="0.023"></testcase><testcase classname="integration.test_message.CouponCheckAndClosure" name="test_coupon_expiry" time="0.075"></testcase><testcase classname="integration.test_message.CouponCheckAndClosure" name="test_forward_logic_1" time="0.076"></testcase><testcase classname="integration.test_message.CouponCheckAndClosure" name="test_forward_logic_2" time="0.076"></testcase><testcase classname="integration.test_message.CouponCheckAndClosure" name="test_forward_logic_3" time="0.066"></testcase><testcase classname="integration.test_message.CouponCheckAndClosure" name="test_forward_logic_4" time="0.087"></testcase><testcase classname="integration.test_message.CouponCheckAndClosure" name="test_forward_logic_5" time="0.109"></testcase><testcase classname="integration.test_message.CouponCheckAndClosure" name="test_simple_inprogress_from_unused" time="0.074"></testcase><testcase classname="integration.test_message.CouponCheckAndClosure" name="test_validate_dealer" time="0.061"></testcase><testcase classname="integration.test_message.CustomerRegistrationTest" name="test_already_registered_customer" time="0.033"></testcase><testcase classname="integration.test_message.CustomerRegistrationTest" name="test_customer_registration" time="0.032"></testcase><testcase classname="integration.test_message.CustomerRegistrationTest" name="test_invalid_message" time="0.038"></testcase><testcase classname="integration.test_message.CustomerServiceTest" name="test_invalid_service" time="0.066"></testcase><testcase classname="integration.test_message.CustomerServiceTest" name="test_valid_service" time="0.039"></testcase><testcase classname="integration.test_registration.TestDealerRegistration" name="test_new_dealer" time="0.093"></testcase><testcase classname="integration.test_save_form.TestSaveFormRegistration" name="test_fail_registration_mail" time="0.162"><error type="django.utils.datastructures.MultiValueDictKeyError" message="&quot;Key 'mobile_number' not found in &lt;QueryDict: {u'phone_number': [u'9999999999'], u'name': [u'TestASCUser'], u'pincode': [u'111111'], u'address': [u'TestASCUser Address'], u'password': [u'password'], u'email': [u'TestASCUser@TestASCUser.com']}&gt;&quot;&#10;-------------------- &gt;&gt; begin captured logging &lt;&lt; --------------------&#10;django.request: ERROR: Internal Server Error: /save/asc&#10;Traceback (most recent call last):&#10;  File &quot;/home/sattva/workspace/python/gladminds-branch/eggs/Django-1.5.5-py2.7.egg/django/core/handlers/base.py&quot;, line 115, in get_response&#10;    response = callback(request, *callback_args, **callback_kwargs)&#10;  File &quot;/home/sattva/workspace/python/gladminds-branch/src/gladminds/views.py&quot;, line 138, in register_user&#10;    status = save_user[user](request.POST)&#10;  File &quot;/home/sattva/workspace/python/gladminds-branch/src/gladminds/views.py&quot;, line 105, in save_asc_registeration&#10;    if common.RegisteredASC.objects.filter(phone_number=data['mobile_number'])\&#10;  File &quot;/home/sattva/workspace/python/gladminds-branch/eggs/Django-1.5.5-py2.7.egg/django/utils/datastructures.py&quot;, line 295, in __getitem__&#10;    raise MultiValueDictKeyError(&quot;Key %r not found in %r&quot; % (key, self))&#10;MultiValueDictKeyError: &quot;Key 'mobile_number' not found in &lt;QueryDict: {u'phone_number': [u'9999999999'], u'name': [u'TestASCUser'], u'pincode': [u'111111'], u'address': [u'TestASCUser Address'], u'password': [u'password'], u'email': [u'TestASCUser@TestASCUser.com']}&gt;&quot;&#10;--------------------- &gt;&gt; end captured logging &lt;&lt; ---------------------"><![CDATA[  File "/usr/lib/python2.7/unittest/case.py", line 331, in run
    testMethod()
  File "/home/sattva/workspace/python/gladminds-branch/tests/integration/test_save_form.py", line 38, in test_fail_registration_mail
    response = self.client.post('/save/asc', data=data)
  File "/home/sattva/workspace/python/gladminds-branch/eggs/Django-1.5.5-py2.7.egg/django/test/client.py", line 463, in post
    response = super(Client, self).post(path, data=data, content_type=content_type, **extra)
  File "/home/sattva/workspace/python/gladminds-branch/eggs/Django-1.5.5-py2.7.egg/django/test/client.py", line 297, in post
    return self.request(**r)
  File "/home/sattva/workspace/python/gladminds-branch/eggs/Django-1.5.5-py2.7.egg/django/test/client.py", line 424, in request
    six.reraise(*exc_info)
  File "/home/sattva/workspace/python/gladminds-branch/eggs/Django-1.5.5-py2.7.egg/django/core/handlers/base.py", line 115, in get_response
    response = callback(request, *callback_args, **callback_kwargs)
  File "/home/sattva/workspace/python/gladminds-branch/src/gladminds/views.py", line 138, in register_user
    status = save_user[user](request.POST)
  File "/home/sattva/workspace/python/gladminds-branch/src/gladminds/views.py", line 105, in save_asc_registeration
    if common.RegisteredASC.objects.filter(phone_number=data['mobile_number'])\
  File "/home/sattva/workspace/python/gladminds-branch/eggs/Django-1.5.5-py2.7.egg/django/utils/datastructures.py", line 295, in __getitem__
    raise MultiValueDictKeyError("Key %r not found in %r" % (key, self))
'"Key \'mobile_number\' not found in <QueryDict: {u\'phone_number\': [u\'9999999999\'], u\'name\': [u\'TestASCUser\'], u\'pincode\': [u\'111111\'], u\'address\': [u\'TestASCUser Address\'], u\'password\': [u\'password\'], u\'email\': [u\'TestASCUser@TestASCUser.com\']}>"\n-------------------- >> begin captured logging << --------------------\ndjango.request: ERROR: Internal Server Error: /save/asc\nTraceback (most recent call last):\n  File "/home/sattva/workspace/python/gladminds-branch/eggs/Django-1.5.5-py2.7.egg/django/core/handlers/base.py", line 115, in get_response\n    response = callback(request, *callback_args, **callback_kwargs)\n  File "/home/sattva/workspace/python/gladminds-branch/src/gladminds/views.py", line 138, in register_user\n    status = save_user[user](request.POST)\n  File "/home/sattva/workspace/python/gladminds-branch/src/gladminds/views.py", line 105, in save_asc_registeration\n    if common.RegisteredASC.objects.filter(phone_number=data[\'mobile_number\'])\\\n  File "/home/sattva/workspace/python/gladminds-branch/eggs/Django-1.5.5-py2.7.egg/django/utils/datastructures.py", line 295, in __getitem__\n    raise MultiValueDictKeyError("Key %r not found in %r" % (key, self))\nMultiValueDictKeyError: "Key \'mobile_number\' not found in <QueryDict: {u\'phone_number\': [u\'9999999999\'], u\'name\': [u\'TestASCUser\'], u\'pincode\': [u\'111111\'], u\'address\': [u\'TestASCUser Address\'], u\'password\': [u\'password\'], u\'email\': [u\'TestASCUser@TestASCUser.com\']}>"\n--------------------- >> end captured logging << ---------------------']]></error></testcase><testcase classname="integration.test_sqs.TestSQSTasks" name="test_send_registration_detail" time="1.123"></testcase><testcase classname="integration.test_sqs.TestSQSTasks" name="test_send_service_detail" time="0.117"></testcase><testcase classname="unit.test_celery.TestCelery" name="test_send_sms" time="0.011"><error type="exceptions.AttributeError" message="'dict' object has no attribute 'successful'"><![CDATA[Traceback (most recent call last):
  File "/usr/lib/python2.7/unittest/case.py", line 331, in run
    testMethod()
  File "/home/sattva/workspace/python/gladminds-branch/eggs/Django-1.5.5-py2.7.egg/django/test/utils.py", line 224, in inner
    return test_func(*args, **kwargs)
  File "/home/sattva/workspace/python/gladminds-branch/tests/unit/test_celery.py", line 21, in test_send_sms
    self.assertTrue(result.successful())
AttributeError: 'dict' object has no attribute 'successful'
]]></error></testcase><testcase classname="unit.test_celery.TestCelery" name="test_send_sms_fail" time="0.012"><error type="exceptions.AttributeError" message="'dict' object has no attribute 'successful'"><![CDATA[Traceback (most recent call last):
  File "/usr/lib/python2.7/unittest/case.py", line 331, in run
    testMethod()
  File "/home/sattva/workspace/python/gladminds-branch/eggs/Django-1.5.5-py2.7.egg/django/test/utils.py", line 224, in inner
    return test_func(*args, **kwargs)
  File "/home/sattva/workspace/python/gladminds-branch/tests/unit/test_celery.py", line 27, in test_send_sms_fail
    self.assertFalse(result.successful())
AttributeError: 'dict' object has no attribute 'successful'
]]></error></testcase><testcase classname="unit.test_resource.GladmindsResourcesTest" name="test_close_coupon" time="0.005"><error type="exceptions.IOError" message="[Errno 2] No such file or directory: '/home/sattva/workspace/python/gladminds-branch/src/../etc/data/data.json'"><![CDATA[Traceback (most recent call last):
  File "/usr/lib/python2.7/unittest/case.py", line 322, in run
    self.setUp()
  File "/home/sattva/workspace/python/gladminds-branch/tests/unit/test_resource.py", line 17, in setUp
    self.data = json.load(open(file_path))['data']
IOError: [Errno 2] No such file or directory: '/home/sattva/workspace/python/gladminds-branch/src/../etc/data/data.json'
]]></error></testcase><testcase classname="unit.test_resource.GladmindsResourcesTest" name="test_coupon_initiators" time="0.005"><error type="exceptions.IOError" message="[Errno 2] No such file or directory: '/home/sattva/workspace/python/gladminds-branch/src/../etc/data/data.json'"><![CDATA[Traceback (most recent call last):
  File "/usr/lib/python2.7/unittest/case.py", line 322, in run
    self.setUp()
  File "/home/sattva/workspace/python/gladminds-branch/tests/unit/test_resource.py", line 17, in setUp
    self.data = json.load(open(file_path))['data']
IOError: [Errno 2] No such file or directory: '/home/sattva/workspace/python/gladminds-branch/src/../etc/data/data.json'
]]></error></testcase><testcase classname="unit.test_resource.GladmindsResourcesTest" name="test_customer_service_detail" time="0.005"><error type="exceptions.IOError" message="[Errno 2] No such file or directory: '/home/sattva/workspace/python/gladminds-branch/src/../etc/data/data.json'"><![CDATA[Traceback (most recent call last):
  File "/usr/lib/python2.7/unittest/case.py", line 322, in run
    self.setUp()
  File "/home/sattva/workspace/python/gladminds-branch/tests/unit/test_resource.py", line 17, in setUp
    self.data = json.load(open(file_path))['data']
IOError: [Errno 2] No such file or directory: '/home/sattva/workspace/python/gladminds-branch/src/../etc/data/data.json'
]]></error></testcase><testcase classname="unit.test_resource.GladmindsResourcesTest" name="test_dispatch_gladminds" time="0.005"><error type="exceptions.IOError" message="[Errno 2] No such file or directory: '/home/sattva/workspace/python/gladminds-branch/src/../etc/data/data.json'"><![CDATA[Traceback (most recent call last):
  File "/usr/lib/python2.7/unittest/case.py", line 322, in run
    self.setUp()
  File "/home/sattva/workspace/python/gladminds-branch/tests/unit/test_resource.py", line 17, in setUp
    self.data = json.load(open(file_path))['data']
IOError: [Errno 2] No such file or directory: '/home/sattva/workspace/python/gladminds-branch/src/../etc/data/data.json'
]]></error></testcase><testcase classname="unit.test_resource.GladmindsResourcesTest" name="test_expire_or_close_less_kms_coupon" time="0.005"><error type="exceptions.IOError" message="[Errno 2] No such file or directory: '/home/sattva/workspace/python/gladminds-branch/src/../etc/data/data.json'"><![CDATA[Traceback (most recent call last):
  File "/usr/lib/python2.7/unittest/case.py", line 322, in run
    self.setUp()
  File "/home/sattva/workspace/python/gladminds-branch/tests/unit/test_resource.py", line 17, in setUp
    self.data = json.load(open(file_path))['data']
IOError: [Errno 2] No such file or directory: '/home/sattva/workspace/python/gladminds-branch/src/../etc/data/data.json'
]]></error></testcase><testcase classname="unit.test_resource.GladmindsResourcesTest" name="test_format_message" time="0.005"><error type="exceptions.IOError" message="[Errno 2] No such file or directory: '/home/sattva/workspace/python/gladminds-branch/src/../etc/data/data.json'"><![CDATA[Traceback (most recent call last):
  File "/usr/lib/python2.7/unittest/case.py", line 322, in run
    self.setUp()
  File "/home/sattva/workspace/python/gladminds-branch/tests/unit/test_resource.py", line 17, in setUp
    self.data = json.load(open(file_path))['data']
IOError: [Errno 2] No such file or directory: '/home/sattva/workspace/python/gladminds-branch/src/../etc/data/data.json'
]]></error></testcase><testcase classname="unit.test_resource.GladmindsResourcesTest" name="test_inprogress_coupon" time="0.005"><error type="exceptions.IOError" message="[Errno 2] No such file or directory: '/home/sattva/workspace/python/gladminds-branch/src/../etc/data/data.json'"><![CDATA[Traceback (most recent call last):
  File "/usr/lib/python2.7/unittest/case.py", line 322, in run
    self.setUp()
  File "/home/sattva/workspace/python/gladminds-branch/tests/unit/test_resource.py", line 17, in setUp
    self.data = json.load(open(file_path))['data']
IOError: [Errno 2] No such file or directory: '/home/sattva/workspace/python/gladminds-branch/src/../etc/data/data.json'
]]></error></testcase><testcase classname="unit.test_resource.GladmindsResourcesTest" name="test_is_valid_data" time="0.005"><error type="exceptions.IOError" message="[Errno 2] No such file or directory: '/home/sattva/workspace/python/gladminds-branch/src/../etc/data/data.json'"><![CDATA[Traceback (most recent call last):
  File "/usr/lib/python2.7/unittest/case.py", line 322, in run
    self.setUp()
  File "/home/sattva/workspace/python/gladminds-branch/tests/unit/test_resource.py", line 17, in setUp
    self.data = json.load(open(file_path))['data']
IOError: [Errno 2] No such file or directory: '/home/sattva/workspace/python/gladminds-branch/src/../etc/data/data.json'
]]></error></testcase><testcase classname="unit.test_resource.GladmindsResourcesTest" name="test_no_available_coupons" time="0.005"><error type="exceptions.IOError" message="[Errno 2] No such file or directory: '/home/sattva/workspace/python/gladminds-branch/src/../etc/data/data.json'"><![CDATA[Traceback (most recent call last):
  File "/usr/lib/python2.7/unittest/case.py", line 322, in run
    self.setUp()
  File "/home/sattva/workspace/python/gladminds-branch/tests/unit/test_resource.py", line 17, in setUp
    self.data = json.load(open(file_path))['data']
IOError: [Errno 2] No such file or directory: '/home/sattva/workspace/python/gladminds-branch/src/../etc/data/data.json'
]]></error></testcase><testcase classname="unit.test_resource.GladmindsResourcesTest" name="test_register_customer" time="0.005"><error type="exceptions.IOError" message="[Errno 2] No such file or directory: '/home/sattva/workspace/python/gladminds-branch/src/../etc/data/data.json'"><![CDATA[Traceback (most recent call last):
  File "/usr/lib/python2.7/unittest/case.py", line 322, in run
    self.setUp()
  File "/home/sattva/workspace/python/gladminds-branch/tests/unit/test_resource.py", line 17, in setUp
    self.data = json.load(open(file_path))['data']
IOError: [Errno 2] No such file or directory: '/home/sattva/workspace/python/gladminds-branch/src/../etc/data/data.json'
]]></error></testcase><testcase classname="unit.test_smsparser.SmsParserTest" name="test_invalid_keyword" time="0.017"></testcase><testcase classname="unit.test_smsparser.SmsParserTest" name="test_invalid_keyword_2" time="0.006"></testcase><testcase classname="unit.test_smsparser.SmsParserTest" name="test_invalid_message_format" time="0.016"></testcase><testcase classname="unit.test_smsparser.SmsParserTest" name="test_sms_parse" time="0.016"></testcase><testcase classname="unit.test_celery.TestCronjobs" name="test_expire_service_coupon" time="0.009"><error type="exceptions.NameError" message="global name 'expire_service_coupon' is not defined&#10;-------------------- &gt;&gt; begin captured logging &lt;&lt; --------------------&#10;gladminds: INFO: triggered update_coupon_data&#10;py.warnings: WARNING: /home/sattva/workspace/python/gladminds-branch/eggs/Django-1.5.5-py2.7.egg/django/db/models/fields/__init__.py:827: RuntimeWarning: DateTimeField received a naive datetime (2014-05-13 21:07:43.747750) while time zone support is active.&#10;  RuntimeWarning)&#10;&#10;gladminds: INFO: triggered update_coupon_data&#10;py.warnings: WARNING: /home/sattva/workspace/python/gladminds-branch/eggs/Django-1.5.5-py2.7.egg/django/db/models/fields/__init__.py:827: RuntimeWarning: DateTimeField received a naive datetime (2014-05-11 21:07:43.749929) while time zone support is active.&#10;  RuntimeWarning)&#10;&#10;py.warnings: WARNING: /home/sattva/workspace/python/gladminds-branch/eggs/Django-1.5.5-py2.7.egg/django/db/models/fields/__init__.py:827: RuntimeWarning: DateTimeField received a naive datetime (2014-05-02 21:07:43.749919) while time zone support is active.&#10;  RuntimeWarning)&#10;&#10;py.warnings: WARNING: /home/sattva/workspace/python/gladminds-branch/eggs/Django-1.5.5-py2.7.egg/django/db/models/fields/__init__.py:827: RuntimeWarning: DateTimeField received a naive datetime (2014-05-14 21:07:43.749934) while time zone support is active.&#10;  RuntimeWarning)&#10;&#10;py.warnings: WARNING: /home/sattva/workspace/python/gladminds-branch/eggs/Django-1.5.5-py2.7.egg/django/db/models/fields/__init__.py:827: RuntimeWarning: DateTimeField received a naive datetime (2014-05-11 21:07:43.750956) while time zone support is active.&#10;  RuntimeWarning)&#10;&#10;py.warnings: WARNING: /home/sattva/workspace/python/gladminds-branch/eggs/Django-1.5.5-py2.7.egg/django/db/models/fields/__init__.py:827: RuntimeWarning: DateTimeField received a naive datetime (2014-04-02 21:07:43.750947) while time zone support is active.&#10;  RuntimeWarning)&#10;&#10;py.warnings: WARNING: /home/sattva/workspace/python/gladminds-branch/eggs/Django-1.5.5-py2.7.egg/django/db/models/fields/__init__.py:827: RuntimeWarning: DateTimeField received a naive datetime (2014-06-01 21:07:43.750961) while time zone support is active.&#10;  RuntimeWarning)&#10;&#10;py.warnings: WARNING: /home/sattva/workspace/python/gladminds-branch/eggs/Django-1.5.5-py2.7.egg/django/db/models/fields/__init__.py:827: RuntimeWarning: DateTimeField received a naive datetime (2014-05-11 21:07:43.751951) while time zone support is active.&#10;  RuntimeWarning)&#10;&#10;py.warnings: WARNING: /home/sattva/workspace/python/gladminds-branch/eggs/Django-1.5.5-py2.7.egg/django/db/models/fields/__init__.py:827: RuntimeWarning: DateTimeField received a naive datetime (2014-05-02 21:07:43.752592) while time zone support is active.&#10;  RuntimeWarning)&#10;&#10;py.warnings: WARNING: /home/sattva/workspace/python/gladminds-branch/eggs/Django-1.5.5-py2.7.egg/django/db/models/fields/__init__.py:827: RuntimeWarning: DateTimeField received a naive datetime (2014-05-10 21:07:43.752601) while time zone support is active.&#10;  RuntimeWarning)&#10;&#10;--------------------- &gt;&gt; end captured logging &lt;&lt; ---------------------"><![CDATA[  File "/usr/lib/python2.7/unittest/case.py", line 331, in run
    testMethod()
  File "/home/sattva/workspace/python/gladminds-branch/tests/unit/test_celery.py", line 73, in test_expire_service_coupon
    expire_service_coupon()
"global name 'expire_service_coupon' is not defined\n-------------------- >> begin captured logging << --------------------\ngladminds: INFO: triggered update_coupon_data\npy.warnings: WARNING: /home/sattva/workspace/python/gladminds-branch/eggs/Django-1.5.5-py2.7.egg/django/db/models/fields/__init__.py:827: RuntimeWarning: DateTimeField received a naive datetime (2014-05-13 21:07:43.747750) while time zone support is active.\n  RuntimeWarning)\n\ngladminds: INFO: triggered update_coupon_data\npy.warnings: WARNING: /home/sattva/workspace/python/gladminds-branch/eggs/Django-1.5.5-py2.7.egg/django/db/models/fields/__init__.py:827: RuntimeWarning: DateTimeField received a naive datetime (2014-05-11 21:07:43.749929) while time zone support is active.\n  RuntimeWarning)\n\npy.warnings: WARNING: /home/sattva/workspace/python/gladminds-branch/eggs/Django-1.5.5-py2.7.egg/django/db/models/fields/__init__.py:827: RuntimeWarning: DateTimeField received a naive datetime (2014-05-02 21:07:43.749919) while time zone support is active.\n  RuntimeWarning)\n\npy.warnings: WARNING: /home/sattva/workspace/python/gladminds-branch/eggs/Django-1.5.5-py2.7.egg/django/db/models/fields/__init__.py:827: RuntimeWarning: DateTimeField received a naive datetime (2014-05-14 21:07:43.749934) while time zone support is active.\n  RuntimeWarning)\n\npy.warnings: WARNING: /home/sattva/workspace/python/gladminds-branch/eggs/Django-1.5.5-py2.7.egg/django/db/models/fields/__init__.py:827: RuntimeWarning: DateTimeField received a naive datetime (2014-05-11 21:07:43.750956) while time zone support is active.\n  RuntimeWarning)\n\npy.warnings: WARNING: /home/sattva/workspace/python/gladminds-branch/eggs/Django-1.5.5-py2.7.egg/django/db/models/fields/__init__.py:827: RuntimeWarning: DateTimeField received a naive datetime (2014-04-02 21:07:43.750947) while time zone support is active.\n  RuntimeWarning)\n\npy.warnings: WARNING: /home/sattva/workspace/python/gladminds-branch/eggs/Django-1.5.5-py2.7.egg/django/db/models/fields/__init__.py:827: RuntimeWarning: DateTimeField received a naive datetime (2014-06-01 21:07:43.750961) while time zone support is active.\n  RuntimeWarning)\n\npy.warnings: WARNING: /home/sattva/workspace/python/gladminds-branch/eggs/Django-1.5.5-py2.7.egg/django/db/models/fields/__init__.py:827: RuntimeWarning: DateTimeField received a naive datetime (2014-05-11 21:07:43.751951) while time zone support is active.\n  RuntimeWarning)\n\npy.warnings: WARNING: /home/sattva/workspace/python/gladminds-branch/eggs/Django-1.5.5-py2.7.egg/django/db/models/fields/__init__.py:827: RuntimeWarning: DateTimeField received a naive datetime (2014-05-02 21:07:43.752592) while time zone support is active.\n  RuntimeWarning)\n\npy.warnings: WARNING: /home/sattva/workspace/python/gladminds-branch/eggs/Django-1.5.5-py2.7.egg/django/db/models/fields/__init__.py:827: RuntimeWarning: DateTimeField received a naive datetime (2014-05-10 21:07:43.752601) while time zone support is active.\n  RuntimeWarning)\n\n--------------------- >> end captured logging << ---------------------"]]></error></testcase><testcase classname="unit.test_celery.TestCronjobs" name="test_get_data_feed_log_detail" time="0.028"></testcase><testcase classname="unit.test_celery.TestTasks" name="test_tasks" time="3.055"></testcase><testcase classname="unit.test_csvfeed.CSVFeedTest" name="test_brandproducttypefeed" time="0.007"></testcase><testcase classname="unit.test_csvfeed.CSVFeedTest" name="test_import_duplicate_feed" time="0.008"></testcase><testcase classname="unit.test_unit.TestAssertWorks" name="test_assert_equals" time="0.000"></testcase><testcase classname="unit.test_unit.TestAssertWorks" name="test_assert_true" time="0.000"></testcase></testsuite>