<?xml version="1.0" encoding="UTF-8"?><testsuite name="nosetests" tests="72" errors="38" failures="5" skip="1"><testcase classname="integration.test_afterbuy.TestAfterbuy" name="test_check_login" time="1.784"><system-out><![CDATA[%%%%%%%% 200 {"status": 1, "username": "testuser", "sourceURL": "", "thumbURL": "", "message": "Success!", "id": "GMS172C9E6E5EAE", "unique_id": "GMS172C9E6E5EAE"}
[<GladMindUsers: 99999999>]
Vary: Cookie
Content-Type: text/html; charset=utf-8

{"status": "1", "username": "testuser", "id": "GMS172C9E6E5EAE", "unique_id": "GMS172C9E6E5EAE"}
]]></system-out></testcase><testcase classname="integration.test_afterbuy.TestAfterbuy" name="test_create_item" time="0.078"></testcase><testcase classname="integration.test_afterbuy.TestAfterbuy" name="test_create_new_user" time="0.276"><system-out><![CDATA[%%%%%%%% 200 {"status": 1, "username": "testuser", "sourceURL": "", "thumbURL": "", "message": "Success!", "id": "GMS17AB71214FE2", "unique_id": "GMS17AB71214FE2"}
[<GladMindUsers: 99999999>]
]]></system-out></testcase><testcase classname="integration.test_afterbuy.TestAfterbuy" name="test_product_details" time="0.018"></testcase><testcase classname="integration.test_api.AfterBuyIntegrationTests" name="test_brands" time="0.910"></testcase><testcase classname="integration.test_api.AfterBuyIntegrationTests" name="test_products" time="0.168"></testcase><testcase classname="integration.test_api.AfterBuyIntegrationTests" name="test_users" time="0.164"></testcase><testcase classname="integration.test_celery.CeleryTestCaseBase" name="test_delay_message" time="0.001"><error type="exceptions.IOError" message="[Errno 2] No such file or directory: '/home/hasher/workspace/gladminds/src/../etc/data/template.json'"><![CDATA[Traceback (most recent call last):
  File "/usr/lib/python2.7/unittest/case.py", line 322, in run
    self.setUp()
  File "/home/hasher/workspace/gladminds/tests/integration/test_celery.py", line 15, in setUp
    super(CeleryTestCaseBase, self).setUp()
  File "/home/hasher/workspace/gladminds/tests/integration/base_integration.py", line 15, in setUp
    message_templates = json.loads(open(file_path).read())
IOError: [Errno 2] No such file or directory: '/home/hasher/workspace/gladminds/src/../etc/data/template.json'
]]></error></testcase><testcase classname="integration.test_feeds.FeedsResourceTest" name="test_asc_feed" time="0.535"><error type="src.gladminds.aftersell.models.common.DoesNotExist" message="RegisteredASC matching query does not exist.&#10;-------------------- &gt;&gt; begin captured logging &lt;&lt; --------------------&#10;gladminds: INFO: New dealer Registration with id - GMDEALER001&#10;gladminds: INFO: [Exception: new_ registration]: Group matching query does not exist.&#10;gladminds: INFO: [Exception: new_ registration]: User matching query does not exist.&#10;gladminds: INFO: dealer GMDEALER001 registered successfully&#10;gladminds: INFO: New ASC Registration with id - ASC001&#10;gladminds: INFO: [Exception: new_ registration]: Group matching query does not exist.&#10;gladminds: INFO: [Exception: new_ registration]: User matching query does not exist.&#10;gladminds: INFO: ASC ASC001 registered successfully&#10;py.warnings: WARNING: /home/hasher/workspace/gladminds/eggs/Django-1.6.4-py2.7.egg/django/db/models/fields/__init__.py:903: RuntimeWarning: DateTimeField DataFeedLog.timestamp received a naive datetime (2014-10-13 12:22:28.204573) while time zone support is active.&#10;  RuntimeWarning)&#10;&#10;--------------------- &gt;&gt; end captured logging &lt;&lt; ---------------------"><![CDATA[  File "/usr/lib/python2.7/unittest/case.py", line 331, in run
    testMethod()
  File "/home/hasher/workspace/gladminds/tests/integration/test_feeds.py", line 267, in test_asc_feed
    asc = RegisteredASC.objects.get(asc_id='ASC001')
  File "/home/hasher/workspace/gladminds/eggs/Django-1.6.4-py2.7.egg/django/db/models/manager.py", line 151, in get
    return self.get_queryset().get(*args, **kwargs)
  File "/home/hasher/workspace/gladminds/eggs/Django-1.6.4-py2.7.egg/django/db/models/query.py", line 307, in get
    self.model._meta.object_name)
'RegisteredASC matching query does not exist.\n-------------------- >> begin captured logging << --------------------\ngladminds: INFO: New dealer Registration with id - GMDEALER001\ngladminds: INFO: [Exception: new_ registration]: Group matching query does not exist.\ngladminds: INFO: [Exception: new_ registration]: User matching query does not exist.\ngladminds: INFO: dealer GMDEALER001 registered successfully\ngladminds: INFO: New ASC Registration with id - ASC001\ngladminds: INFO: [Exception: new_ registration]: Group matching query does not exist.\ngladminds: INFO: [Exception: new_ registration]: User matching query does not exist.\ngladminds: INFO: ASC ASC001 registered successfully\npy.warnings: WARNING: /home/hasher/workspace/gladminds/eggs/Django-1.6.4-py2.7.egg/django/db/models/fields/__init__.py:903: RuntimeWarning: DateTimeField DataFeedLog.timestamp received a naive datetime (2014-10-13 12:22:28.204573) while time zone support is active.\n  RuntimeWarning)\n\n--------------------- >> end captured logging << ---------------------']]></error></testcase><testcase classname="integration.test_feeds.FeedsResourceTest" name="test_authentication" time="0.863"></testcase><testcase classname="integration.test_feeds.FeedsResourceTest" name="test_coupon_redamption_feed" time="1.982"></testcase><testcase classname="integration.test_feeds.FeedsResourceTest" name="test_coupon_status_on_dispatch_feed" time="0.000"><skipped type="unittest.case.SkipTest" message="Skipping Adding this functionality in future"><![CDATA[SkipTest: Skipping Adding this functionality in future
]]></skipped></testcase><testcase classname="integration.test_feeds.FeedsResourceTest" name="test_coupon_status_without_ucn" time="0.525"></testcase><testcase classname="integration.test_feeds.FeedsResourceTest" name="test_credit_note_feed" time="0.935"><failure type="exceptions.AssertionError" message="'2013-12-06' != '2013-12-07'&#10;-------------------- &gt;&gt; begin captured logging &lt;&lt; --------------------&#10;gladminds: INFO: [Info: ProductDispatchFeed_product_data]: ProductData matching query does not exist.&#10;gladminds: INFO: New dealer Registration with id - GMDEALER001&#10;gladminds: INFO: [Exception: new_ registration]: Group matching query does not exist.&#10;gladminds: INFO: [Exception: new_ registration]: User matching query does not exist.&#10;gladminds: INFO: dealer GMDEALER001 registered successfully&#10;gladminds: INFO: [Exception: BrandProductTypeFeed_brand_data]: BrandData matching query does not exist.&#10;gladminds: INFO: triggered update_coupon_data&#10;gladminds: INFO: [Successful: ProductDispatchFeed_product_data_save]:VIN - XXXXXXXXXX&#10;gladminds: INFO: [Successful: ProductDispatchFeed_product_data_save]:VIN - XXXXXXXXXX UCN - USC001&#10;gladminds: INFO: [Successful: ProductDispatchFeed_product_data_save]:VIN - XXXXXXXXXX UCN - USC002&#10;py.warnings: WARNING: /home/hasher/workspace/gladminds/eggs/Django-1.6.4-py2.7.egg/django/db/models/fields/__init__.py:903: RuntimeWarning: DateTimeField DataFeedLog.timestamp received a naive datetime (2014-10-13 12:22:32.098911) while time zone support is active.&#10;  RuntimeWarning)&#10;&#10;gladminds: INFO: [Exception: ProductPurchaseFeed_customer_data]: GladMindUsers matching query does not exist.&#10;gladminds: INFO: New customer Registration with id - 07343EE75B&#10;gladminds: INFO: [Exception: new_ registration]: Group matching query does not exist.&#10;gladminds: INFO: [Exception: new_ registration]: User matching query does not exist.&#10;gladminds: INFO: customer 07343EE75B registered successfully&#10;py.warnings: WARNING: /home/hasher/workspace/gladminds/eggs/Django-1.6.4-py2.7.egg/django/db/models/fields/__init__.py:903: RuntimeWarning: DateTimeField GladMindUsers.registration_date received a naive datetime (2014-10-13 12:22:32.437818) while time zone support is active.&#10;  RuntimeWarning)&#10;&#10;gladminds: INFO: triggered update_coupon_data&#10;gladminds: INFO: [Exception]: Signal-In Update Coupon Data MessageTemplate matching query does not exist.&#10;py.warnings: WARNING: /home/hasher/workspace/gladminds/eggs/Django-1.6.4-py2.7.egg/django/db/models/fields/__init__.py:903: RuntimeWarning: DateTimeField DataFeedLog.timestamp received a naive datetime (2014-10-13 12:22:32.466097) while time zone support is active.&#10;  RuntimeWarning)&#10;&#10;py.warnings: WARNING: /home/hasher/workspace/gladminds/eggs/Django-1.6.4-py2.7.egg/django/db/models/fields/__init__.py:848: RuntimeWarning: DateTimeField CouponData.credit_date received a naive datetime (2013-12-06 00:00:00) while time zone support is active.&#10;  RuntimeWarning)&#10;&#10;gladminds: INFO: updated credit details:: vin : XXXXXXXXXX coupon : USC001 service_type : 1&#10;py.warnings: WARNING: /home/hasher/workspace/gladminds/eggs/Django-1.6.4-py2.7.egg/django/db/models/fields/__init__.py:903: RuntimeWarning: DateTimeField DataFeedLog.timestamp received a naive datetime (2014-10-13 12:22:32.504786) while time zone support is active.&#10;  RuntimeWarning)&#10;&#10;--------------------- &gt;&gt; end captured logging &lt;&lt; ---------------------"><![CDATA[  File "/usr/lib/python2.7/unittest/case.py", line 331, in run
    testMethod()
  File "/home/hasher/workspace/gladminds/tests/integration/test_feeds.py", line 310, in test_credit_note_feed
    self.assertEquals(credit_date, '2013-12-07')
  File "/usr/lib/python2.7/unittest/case.py", line 515, in assertEqual
    assertion_func(first, second, msg=msg)
  File "/usr/lib/python2.7/unittest/case.py", line 508, in _baseAssertEqual
    raise self.failureException(msg)
"'2013-12-06' != '2013-12-07'\n-------------------- >> begin captured logging << --------------------\ngladminds: INFO: [Info: ProductDispatchFeed_product_data]: ProductData matching query does not exist.\ngladminds: INFO: New dealer Registration with id - GMDEALER001\ngladminds: INFO: [Exception: new_ registration]: Group matching query does not exist.\ngladminds: INFO: [Exception: new_ registration]: User matching query does not exist.\ngladminds: INFO: dealer GMDEALER001 registered successfully\ngladminds: INFO: [Exception: BrandProductTypeFeed_brand_data]: BrandData matching query does not exist.\ngladminds: INFO: triggered update_coupon_data\ngladminds: INFO: [Successful: ProductDispatchFeed_product_data_save]:VIN - XXXXXXXXXX\ngladminds: INFO: [Successful: ProductDispatchFeed_product_data_save]:VIN - XXXXXXXXXX UCN - USC001\ngladminds: INFO: [Successful: ProductDispatchFeed_product_data_save]:VIN - XXXXXXXXXX UCN - USC002\npy.warnings: WARNING: /home/hasher/workspace/gladminds/eggs/Django-1.6.4-py2.7.egg/django/db/models/fields/__init__.py:903: RuntimeWarning: DateTimeField DataFeedLog.timestamp received a naive datetime (2014-10-13 12:22:32.098911) while time zone support is active.\n  RuntimeWarning)\n\ngladminds: INFO: [Exception: ProductPurchaseFeed_customer_data]: GladMindUsers matching query does not exist.\ngladminds: INFO: New customer Registration with id - 07343EE75B\ngladminds: INFO: [Exception: new_ registration]: Group matching query does not exist.\ngladminds: INFO: [Exception: new_ registration]: User matching query does not exist.\ngladminds: INFO: customer 07343EE75B registered successfully\npy.warnings: WARNING: /home/hasher/workspace/gladminds/eggs/Django-1.6.4-py2.7.egg/django/db/models/fields/__init__.py:903: RuntimeWarning: DateTimeField GladMindUsers.registration_date received a naive datetime (2014-10-13 12:22:32.437818) while time zone support is active.\n  RuntimeWarning)\n\ngladminds: INFO: triggered update_coupon_data\ngladminds: INFO: [Exception]: Signal-In Update Coupon Data MessageTemplate matching query does not exist.\npy.warnings: WARNING: /home/hasher/workspace/gladminds/eggs/Django-1.6.4-py2.7.egg/django/db/models/fields/__init__.py:903: RuntimeWarning: DateTimeField DataFeedLog.timestamp received a naive datetime (2014-10-13 12:22:32.466097) while time zone support is active.\n  RuntimeWarning)\n\npy.warnings: WARNING: /home/hasher/workspace/gladminds/eggs/Django-1.6.4-py2.7.egg/django/db/models/fields/__init__.py:848: RuntimeWarning: DateTimeField CouponData.credit_date received a naive datetime (2013-12-06 00:00:00) while time zone support is active.\n  RuntimeWarning)\n\ngladminds: INFO: updated credit details:: vin : XXXXXXXXXX coupon : USC001 service_type : 1\npy.warnings: WARNING: /home/hasher/workspace/gladminds/eggs/Django-1.6.4-py2.7.egg/django/db/models/fields/__init__.py:903: RuntimeWarning: DateTimeField DataFeedLog.timestamp received a naive datetime (2014-10-13 12:22:32.504786) while time zone support is active.\n  RuntimeWarning)\n\n--------------------- >> end captured logging << ---------------------"]]></failure></testcase><testcase classname="integration.test_feeds.FeedsResourceTest" name="test_old_fsc_feed" time="0.954"></testcase><testcase classname="integration.test_feeds.FeedsResourceTest" name="test_partial_fail" time="0.858"><failure type="exceptions.AssertionError" message="'FAILURE' != 'SUCCESS'&#10;-------------------- &gt;&gt; begin captured logging &lt;&lt; --------------------&#10;gladminds: INFO: New dealer Registration with id - GMDEALER002&#10;gladminds: INFO: [Exception: new_ registration]: Group matching query does not exist.&#10;gladminds: INFO: [Exception: new_ registration]: User matching query does not exist.&#10;gladminds: INFO: dealer GMDEALER002 registered successfully&#10;gladminds: INFO: [Exception:  DealerAndServiceAdvisorFeed_sa]: ServiceAdvisor matching query does not exist.&#10;gladminds: INFO: New SA Registration with id - GMDEALER001SA02&#10;gladminds: INFO: [Exception: new_ registration]: Group matching query does not exist.&#10;gladminds: INFO: [Exception: new_ registration]: User matching query does not exist.&#10;gladminds: INFO: SA GMDEALER001SA02 registered successfully&#10;gladminds: INFO: New dealer Registration with id - GMDEALER001&#10;gladminds: INFO: [Exception: new_ registration]: User matching query does not exist.&#10;gladminds: INFO: dealer GMDEALER001 registered successfully&#10;gladminds: INFO: [Exception:  DealerAndServiceAdvisorFeed_sa]: ServiceAdvisor matching query does not exist.&#10;gladminds: INFO: New SA Registration with id - None&#10;gladminds: INFO: SA id is not provided.&#10;gladminds: ERROR: SA id is not provided.&#10;py.warnings: WARNING: /home/hasher/workspace/gladminds/eggs/Django-1.6.4-py2.7.egg/django/db/models/fields/__init__.py:903: RuntimeWarning: DateTimeField DataFeedLog.timestamp received a naive datetime (2014-10-13 12:22:34.337219) while time zone support is active.&#10;  RuntimeWarning)&#10;&#10;--------------------- &gt;&gt; end captured logging &lt;&lt; ---------------------"><![CDATA[  File "/usr/lib/python2.7/unittest/case.py", line 331, in run
    testMethod()
  File "/home/hasher/workspace/gladminds/tests/integration/test_feeds.py", line 194, in test_partial_fail
    self.assertEqual(status, 'SUCCESS')
  File "/usr/lib/python2.7/unittest/case.py", line 515, in assertEqual
    assertion_func(first, second, msg=msg)
  File "/usr/lib/python2.7/unittest/case.py", line 508, in _baseAssertEqual
    raise self.failureException(msg)
"'FAILURE' != 'SUCCESS'\n-------------------- >> begin captured logging << --------------------\ngladminds: INFO: New dealer Registration with id - GMDEALER002\ngladminds: INFO: [Exception: new_ registration]: Group matching query does not exist.\ngladminds: INFO: [Exception: new_ registration]: User matching query does not exist.\ngladminds: INFO: dealer GMDEALER002 registered successfully\ngladminds: INFO: [Exception:  DealerAndServiceAdvisorFeed_sa]: ServiceAdvisor matching query does not exist.\ngladminds: INFO: New SA Registration with id - GMDEALER001SA02\ngladminds: INFO: [Exception: new_ registration]: Group matching query does not exist.\ngladminds: INFO: [Exception: new_ registration]: User matching query does not exist.\ngladminds: INFO: SA GMDEALER001SA02 registered successfully\ngladminds: INFO: New dealer Registration with id - GMDEALER001\ngladminds: INFO: [Exception: new_ registration]: User matching query does not exist.\ngladminds: INFO: dealer GMDEALER001 registered successfully\ngladminds: INFO: [Exception:  DealerAndServiceAdvisorFeed_sa]: ServiceAdvisor matching query does not exist.\ngladminds: INFO: New SA Registration with id - None\ngladminds: INFO: SA id is not provided.\ngladminds: ERROR: SA id is not provided.\npy.warnings: WARNING: /home/hasher/workspace/gladminds/eggs/Django-1.6.4-py2.7.egg/django/db/models/fields/__init__.py:903: RuntimeWarning: DateTimeField DataFeedLog.timestamp received a naive datetime (2014-10-13 12:22:34.337219) while time zone support is active.\n  RuntimeWarning)\n\n--------------------- >> end captured logging << ---------------------"]]></failure></testcase><testcase classname="integration.test_feeds.FeedsResourceTest" name="test_product_dispatch" time="1.799"></testcase><testcase classname="integration.test_feeds.FeedsResourceTest" name="test_product_purchase" time="0.325"></testcase><testcase classname="integration.test_feeds.FeedsResourceTest" name="test_service_advisor_dealer_relationship" time="1.755"></testcase><testcase classname="integration.test_feeds.FeedsResourceTest" name="test_service_advisor_feed" time="1.292"></testcase><testcase classname="integration.test_feeds.FeedsResourceTest" name="test_service_advisor_phone_number_updation_logic" time="1.666"></testcase><testcase classname="integration.test_feeds.FeedsResourceTest" name="test_update_customer_number" time="1.271"><failure type="exceptions.AssertionError" message="Customer Phone Number is not updated&#10;-------------------- &gt;&gt; begin captured logging &lt;&lt; --------------------&#10;gladminds: INFO: [Info: ProductDispatchFeed_product_data]: ProductData matching query does not exist.&#10;gladminds: INFO: New dealer Registration with id - GMDEALER001&#10;gladminds: INFO: [Exception: new_ registration]: Group matching query does not exist.&#10;gladminds: INFO: [Exception: new_ registration]: User matching query does not exist.&#10;gladminds: INFO: dealer GMDEALER001 registered successfully&#10;gladminds: INFO: [Exception: BrandProductTypeFeed_brand_data]: BrandData matching query does not exist.&#10;gladminds: INFO: triggered update_coupon_data&#10;gladminds: INFO: [Successful: ProductDispatchFeed_product_data_save]:VIN - XXXXXXXXXX&#10;gladminds: INFO: [Successful: ProductDispatchFeed_product_data_save]:VIN - XXXXXXXXXX UCN - USC001&#10;gladminds: INFO: [Successful: ProductDispatchFeed_product_data_save]:VIN - XXXXXXXXXX UCN - USC002&#10;py.warnings: WARNING: /home/hasher/workspace/gladminds/eggs/Django-1.6.4-py2.7.egg/django/db/models/fields/__init__.py:903: RuntimeWarning: DateTimeField DataFeedLog.timestamp received a naive datetime (2014-10-13 12:22:41.765956) while time zone support is active.&#10;  RuntimeWarning)&#10;&#10;gladminds: INFO: [Exception: ProductPurchaseFeed_customer_data]: GladMindUsers matching query does not exist.&#10;gladminds: INFO: New customer Registration with id - BE9EA81F9F&#10;gladminds: INFO: [Exception: new_ registration]: Group matching query does not exist.&#10;gladminds: INFO: [Exception: new_ registration]: User matching query does not exist.&#10;gladminds: INFO: customer BE9EA81F9F registered successfully&#10;py.warnings: WARNING: /home/hasher/workspace/gladminds/eggs/Django-1.6.4-py2.7.egg/django/db/models/fields/__init__.py:903: RuntimeWarning: DateTimeField GladMindUsers.registration_date received a naive datetime (2014-10-13 12:22:42.094975) while time zone support is active.&#10;  RuntimeWarning)&#10;&#10;gladminds: INFO: triggered update_coupon_data&#10;gladminds: INFO: [Exception]: Signal-In Update Coupon Data MessageTemplate matching query does not exist.&#10;py.warnings: WARNING: /home/hasher/workspace/gladminds/eggs/Django-1.6.4-py2.7.egg/django/db/models/fields/__init__.py:903: RuntimeWarning: DateTimeField DataFeedLog.timestamp received a naive datetime (2014-10-13 12:22:42.123056) while time zone support is active.&#10;  RuntimeWarning)&#10;&#10;gladminds: INFO: [Exception: ProductPurchaseFeed_customer_data]: GladMindUsers matching query does not exist.&#10;gladminds: INFO: New customer Registration with id - C61531F2B4&#10;gladminds: INFO: [Exception: new_ registration]: User matching query does not exist.&#10;gladminds: INFO: customer C61531F2B4 registered successfully&#10;py.warnings: WARNING: /home/hasher/workspace/gladminds/eggs/Django-1.6.4-py2.7.egg/django/db/models/fields/__init__.py:903: RuntimeWarning: DateTimeField GladMindUsers.registration_date received a naive datetime (2014-10-13 12:22:42.445054) while time zone support is active.&#10;  RuntimeWarning)&#10;&#10;py.warnings: WARNING: /home/hasher/workspace/gladminds/eggs/Django-1.6.4-py2.7.egg/django/db/models/fields/__init__.py:903: RuntimeWarning: DateTimeField DataFeedLog.timestamp received a naive datetime (2014-10-13 12:22:42.450799) while time zone support is active.&#10;  RuntimeWarning)&#10;&#10;--------------------- &gt;&gt; end captured logging &lt;&lt; ---------------------"><![CDATA[  File "/usr/lib/python2.7/unittest/case.py", line 331, in run
    testMethod()
  File "/home/hasher/workspace/gladminds/tests/integration/test_feeds.py", line 214, in test_update_customer_number
    self.assertEqual(gm_user[0].phone_number, "+919845340297", "Customer Phone Number is not updated")
  File "/usr/lib/python2.7/unittest/case.py", line 515, in assertEqual
    assertion_func(first, second, msg=msg)
  File "/usr/lib/python2.7/unittest/case.py", line 508, in _baseAssertEqual
    raise self.failureException(msg)
'Customer Phone Number is not updated\n-------------------- >> begin captured logging << --------------------\ngladminds: INFO: [Info: ProductDispatchFeed_product_data]: ProductData matching query does not exist.\ngladminds: INFO: New dealer Registration with id - GMDEALER001\ngladminds: INFO: [Exception: new_ registration]: Group matching query does not exist.\ngladminds: INFO: [Exception: new_ registration]: User matching query does not exist.\ngladminds: INFO: dealer GMDEALER001 registered successfully\ngladminds: INFO: [Exception: BrandProductTypeFeed_brand_data]: BrandData matching query does not exist.\ngladminds: INFO: triggered update_coupon_data\ngladminds: INFO: [Successful: ProductDispatchFeed_product_data_save]:VIN - XXXXXXXXXX\ngladminds: INFO: [Successful: ProductDispatchFeed_product_data_save]:VIN - XXXXXXXXXX UCN - USC001\ngladminds: INFO: [Successful: ProductDispatchFeed_product_data_save]:VIN - XXXXXXXXXX UCN - USC002\npy.warnings: WARNING: /home/hasher/workspace/gladminds/eggs/Django-1.6.4-py2.7.egg/django/db/models/fields/__init__.py:903: RuntimeWarning: DateTimeField DataFeedLog.timestamp received a naive datetime (2014-10-13 12:22:41.765956) while time zone support is active.\n  RuntimeWarning)\n\ngladminds: INFO: [Exception: ProductPurchaseFeed_customer_data]: GladMindUsers matching query does not exist.\ngladminds: INFO: New customer Registration with id - BE9EA81F9F\ngladminds: INFO: [Exception: new_ registration]: Group matching query does not exist.\ngladminds: INFO: [Exception: new_ registration]: User matching query does not exist.\ngladminds: INFO: customer BE9EA81F9F registered successfully\npy.warnings: WARNING: /home/hasher/workspace/gladminds/eggs/Django-1.6.4-py2.7.egg/django/db/models/fields/__init__.py:903: RuntimeWarning: DateTimeField GladMindUsers.registration_date received a naive datetime (2014-10-13 12:22:42.094975) while time zone support is active.\n  RuntimeWarning)\n\ngladminds: INFO: triggered update_coupon_data\ngladminds: INFO: [Exception]: Signal-In Update Coupon Data MessageTemplate matching query does not exist.\npy.warnings: WARNING: /home/hasher/workspace/gladminds/eggs/Django-1.6.4-py2.7.egg/django/db/models/fields/__init__.py:903: RuntimeWarning: DateTimeField DataFeedLog.timestamp received a naive datetime (2014-10-13 12:22:42.123056) while time zone support is active.\n  RuntimeWarning)\n\ngladminds: INFO: [Exception: ProductPurchaseFeed_customer_data]: GladMindUsers matching query does not exist.\ngladminds: INFO: New customer Registration with id - C61531F2B4\ngladminds: INFO: [Exception: new_ registration]: User matching query does not exist.\ngladminds: INFO: customer C61531F2B4 registered successfully\npy.warnings: WARNING: /home/hasher/workspace/gladminds/eggs/Django-1.6.4-py2.7.egg/django/db/models/fields/__init__.py:903: RuntimeWarning: DateTimeField GladMindUsers.registration_date received a naive datetime (2014-10-13 12:22:42.445054) while time zone support is active.\n  RuntimeWarning)\n\npy.warnings: WARNING: /home/hasher/workspace/gladminds/eggs/Django-1.6.4-py2.7.egg/django/db/models/fields/__init__.py:903: RuntimeWarning: DateTimeField DataFeedLog.timestamp received a naive datetime (2014-10-13 12:22:42.450799) while time zone support is active.\n  RuntimeWarning)\n\n--------------------- >> end captured logging << ---------------------']]></failure></testcase><testcase classname="integration.test_home.TestHome" name="test_home" time="0.001"></testcase><testcase classname="integration.test_message.BrandData" name="test_get_all_brand" time="0.001"><error type="exceptions.IOError" message="[Errno 2] No such file or directory: '/home/hasher/workspace/gladminds/src/../etc/data/template.json'"><![CDATA[Traceback (most recent call last):
  File "/usr/lib/python2.7/unittest/case.py", line 322, in run
    self.setUp()
  File "/home/hasher/workspace/gladminds/tests/integration/test_message.py", line 320, in setUp
    super(BrandData, self).setUp()
  File "/home/hasher/workspace/gladminds/tests/integration/base_integration.py", line 15, in setUp
    message_templates = json.loads(open(file_path).read())
IOError: [Errno 2] No such file or directory: '/home/hasher/workspace/gladminds/src/../etc/data/template.json'
]]></error></testcase><testcase classname="integration.test_message.BrandData" name="test_get_all_products_of_a_brand" time="0.001"><error type="exceptions.IOError" message="[Errno 2] No such file or directory: '/home/hasher/workspace/gladminds/src/../etc/data/template.json'"><![CDATA[Traceback (most recent call last):
  File "/usr/lib/python2.7/unittest/case.py", line 322, in run
    self.setUp()
  File "/home/hasher/workspace/gladminds/tests/integration/test_message.py", line 320, in setUp
    super(BrandData, self).setUp()
  File "/home/hasher/workspace/gladminds/tests/integration/base_integration.py", line 15, in setUp
    message_templates = json.loads(open(file_path).read())
IOError: [Errno 2] No such file or directory: '/home/hasher/workspace/gladminds/src/../etc/data/template.json'
]]></error></testcase><testcase classname="integration.test_message.CouponCheckAndClosure" name="test_coupon_expiry" time="0.001"><error type="exceptions.IOError" message="[Errno 2] No such file or directory: '/home/hasher/workspace/gladminds/src/../etc/data/template.json'"><![CDATA[Traceback (most recent call last):
  File "/usr/lib/python2.7/unittest/case.py", line 322, in run
    self.setUp()
  File "/home/hasher/workspace/gladminds/tests/integration/test_message.py", line 95, in setUp
    super(CouponCheckAndClosure, self).setUp()
  File "/home/hasher/workspace/gladminds/tests/integration/base_integration.py", line 15, in setUp
    message_templates = json.loads(open(file_path).read())
IOError: [Errno 2] No such file or directory: '/home/hasher/workspace/gladminds/src/../etc/data/template.json'
]]></error></testcase><testcase classname="integration.test_message.CouponCheckAndClosure" name="test_forward_logic_1" time="0.001"><error type="exceptions.IOError" message="[Errno 2] No such file or directory: '/home/hasher/workspace/gladminds/src/../etc/data/template.json'"><![CDATA[Traceback (most recent call last):
  File "/usr/lib/python2.7/unittest/case.py", line 322, in run
    self.setUp()
  File "/home/hasher/workspace/gladminds/tests/integration/test_message.py", line 95, in setUp
    super(CouponCheckAndClosure, self).setUp()
  File "/home/hasher/workspace/gladminds/tests/integration/base_integration.py", line 15, in setUp
    message_templates = json.loads(open(file_path).read())
IOError: [Errno 2] No such file or directory: '/home/hasher/workspace/gladminds/src/../etc/data/template.json'
]]></error></testcase><testcase classname="integration.test_message.CouponCheckAndClosure" name="test_forward_logic_2" time="0.001"><error type="exceptions.IOError" message="[Errno 2] No such file or directory: '/home/hasher/workspace/gladminds/src/../etc/data/template.json'"><![CDATA[Traceback (most recent call last):
  File "/usr/lib/python2.7/unittest/case.py", line 322, in run
    self.setUp()
  File "/home/hasher/workspace/gladminds/tests/integration/test_message.py", line 95, in setUp
    super(CouponCheckAndClosure, self).setUp()
  File "/home/hasher/workspace/gladminds/tests/integration/base_integration.py", line 15, in setUp
    message_templates = json.loads(open(file_path).read())
IOError: [Errno 2] No such file or directory: '/home/hasher/workspace/gladminds/src/../etc/data/template.json'
]]></error></testcase><testcase classname="integration.test_message.CouponCheckAndClosure" name="test_forward_logic_3" time="0.001"><error type="exceptions.IOError" message="[Errno 2] No such file or directory: '/home/hasher/workspace/gladminds/src/../etc/data/template.json'"><![CDATA[Traceback (most recent call last):
  File "/usr/lib/python2.7/unittest/case.py", line 322, in run
    self.setUp()
  File "/home/hasher/workspace/gladminds/tests/integration/test_message.py", line 95, in setUp
    super(CouponCheckAndClosure, self).setUp()
  File "/home/hasher/workspace/gladminds/tests/integration/base_integration.py", line 15, in setUp
    message_templates = json.loads(open(file_path).read())
IOError: [Errno 2] No such file or directory: '/home/hasher/workspace/gladminds/src/../etc/data/template.json'
]]></error></testcase><testcase classname="integration.test_message.CouponCheckAndClosure" name="test_forward_logic_4" time="0.001"><error type="exceptions.IOError" message="[Errno 2] No such file or directory: '/home/hasher/workspace/gladminds/src/../etc/data/template.json'"><![CDATA[Traceback (most recent call last):
  File "/usr/lib/python2.7/unittest/case.py", line 322, in run
    self.setUp()
  File "/home/hasher/workspace/gladminds/tests/integration/test_message.py", line 95, in setUp
    super(CouponCheckAndClosure, self).setUp()
  File "/home/hasher/workspace/gladminds/tests/integration/base_integration.py", line 15, in setUp
    message_templates = json.loads(open(file_path).read())
IOError: [Errno 2] No such file or directory: '/home/hasher/workspace/gladminds/src/../etc/data/template.json'
]]></error></testcase><testcase classname="integration.test_message.CouponCheckAndClosure" name="test_forward_logic_5" time="0.001"><error type="exceptions.IOError" message="[Errno 2] No such file or directory: '/home/hasher/workspace/gladminds/src/../etc/data/template.json'"><![CDATA[Traceback (most recent call last):
  File "/usr/lib/python2.7/unittest/case.py", line 322, in run
    self.setUp()
  File "/home/hasher/workspace/gladminds/tests/integration/test_message.py", line 95, in setUp
    super(CouponCheckAndClosure, self).setUp()
  File "/home/hasher/workspace/gladminds/tests/integration/base_integration.py", line 15, in setUp
    message_templates = json.loads(open(file_path).read())
IOError: [Errno 2] No such file or directory: '/home/hasher/workspace/gladminds/src/../etc/data/template.json'
]]></error></testcase><testcase classname="integration.test_message.CouponCheckAndClosure" name="test_invalid_ucn_or_sap_id" time="0.001"><error type="exceptions.IOError" message="[Errno 2] No such file or directory: '/home/hasher/workspace/gladminds/src/../etc/data/template.json'"><![CDATA[Traceback (most recent call last):
  File "/usr/lib/python2.7/unittest/case.py", line 322, in run
    self.setUp()
  File "/home/hasher/workspace/gladminds/tests/integration/test_message.py", line 95, in setUp
    super(CouponCheckAndClosure, self).setUp()
  File "/home/hasher/workspace/gladminds/tests/integration/base_integration.py", line 15, in setUp
    message_templates = json.loads(open(file_path).read())
IOError: [Errno 2] No such file or directory: '/home/hasher/workspace/gladminds/src/../etc/data/template.json'
]]></error></testcase><testcase classname="integration.test_message.CouponCheckAndClosure" name="test_simple_inprogress_from_unused" time="0.001"><error type="exceptions.IOError" message="[Errno 2] No such file or directory: '/home/hasher/workspace/gladminds/src/../etc/data/template.json'"><![CDATA[Traceback (most recent call last):
  File "/usr/lib/python2.7/unittest/case.py", line 322, in run
    self.setUp()
  File "/home/hasher/workspace/gladminds/tests/integration/test_message.py", line 95, in setUp
    super(CouponCheckAndClosure, self).setUp()
  File "/home/hasher/workspace/gladminds/tests/integration/base_integration.py", line 15, in setUp
    message_templates = json.loads(open(file_path).read())
IOError: [Errno 2] No such file or directory: '/home/hasher/workspace/gladminds/src/../etc/data/template.json'
]]></error></testcase><testcase classname="integration.test_message.CustomerIdReccovery" name="test_get_sap_id_by_vin" time="0.001"><error type="exceptions.IOError" message="[Errno 2] No such file or directory: '/home/hasher/workspace/gladminds/src/../etc/data/template.json'"><![CDATA[Traceback (most recent call last):
  File "/usr/lib/python2.7/unittest/case.py", line 322, in run
    self.setUp()
  File "/home/hasher/workspace/gladminds/tests/integration/test_message.py", line 346, in setUp
    super(CustomerIdReccovery, self).setUp()
  File "/home/hasher/workspace/gladminds/tests/integration/base_integration.py", line 15, in setUp
    message_templates = json.loads(open(file_path).read())
IOError: [Errno 2] No such file or directory: '/home/hasher/workspace/gladminds/src/../etc/data/template.json'
]]></error></testcase><testcase classname="integration.test_message.CustomerRegistrationTest" name="test_already_registered_customer" time="0.001"><error type="exceptions.IOError" message="[Errno 2] No such file or directory: '/home/hasher/workspace/gladminds/src/../etc/data/template.json'"><![CDATA[Traceback (most recent call last):
  File "/usr/lib/python2.7/unittest/case.py", line 322, in run
    self.setUp()
  File "/home/hasher/workspace/gladminds/tests/integration/test_message.py", line 18, in setUp
    super(CustomerRegistrationTest, self).setUp()
  File "/home/hasher/workspace/gladminds/tests/integration/base_integration.py", line 15, in setUp
    message_templates = json.loads(open(file_path).read())
IOError: [Errno 2] No such file or directory: '/home/hasher/workspace/gladminds/src/../etc/data/template.json'
]]></error></testcase><testcase classname="integration.test_message.CustomerRegistrationTest" name="test_customer_registration" time="0.001"><error type="exceptions.IOError" message="[Errno 2] No such file or directory: '/home/hasher/workspace/gladminds/src/../etc/data/template.json'"><![CDATA[Traceback (most recent call last):
  File "/usr/lib/python2.7/unittest/case.py", line 322, in run
    self.setUp()
  File "/home/hasher/workspace/gladminds/tests/integration/test_message.py", line 18, in setUp
    super(CustomerRegistrationTest, self).setUp()
  File "/home/hasher/workspace/gladminds/tests/integration/base_integration.py", line 15, in setUp
    message_templates = json.loads(open(file_path).read())
IOError: [Errno 2] No such file or directory: '/home/hasher/workspace/gladminds/src/../etc/data/template.json'
]]></error></testcase><testcase classname="integration.test_message.CustomerRegistrationTest" name="test_invalid_message" time="0.001"><error type="exceptions.IOError" message="[Errno 2] No such file or directory: '/home/hasher/workspace/gladminds/src/../etc/data/template.json'"><![CDATA[Traceback (most recent call last):
  File "/usr/lib/python2.7/unittest/case.py", line 322, in run
    self.setUp()
  File "/home/hasher/workspace/gladminds/tests/integration/test_message.py", line 18, in setUp
    super(CustomerRegistrationTest, self).setUp()
  File "/home/hasher/workspace/gladminds/tests/integration/base_integration.py", line 15, in setUp
    message_templates = json.loads(open(file_path).read())
IOError: [Errno 2] No such file or directory: '/home/hasher/workspace/gladminds/src/../etc/data/template.json'
]]></error></testcase><testcase classname="integration.test_message.CustomerServiceTest" name="test_invalid_service" time="0.001"><error type="exceptions.IOError" message="[Errno 2] No such file or directory: '/home/hasher/workspace/gladminds/src/../etc/data/template.json'"><![CDATA[Traceback (most recent call last):
  File "/usr/lib/python2.7/unittest/case.py", line 322, in run
    self.setUp()
  File "/home/hasher/workspace/gladminds/tests/integration/test_message.py", line 59, in setUp
    super(CustomerServiceTest, self).setUp()
  File "/home/hasher/workspace/gladminds/tests/integration/base_integration.py", line 15, in setUp
    message_templates = json.loads(open(file_path).read())
IOError: [Errno 2] No such file or directory: '/home/hasher/workspace/gladminds/src/../etc/data/template.json'
]]></error></testcase><testcase classname="integration.test_message.CustomerServiceTest" name="test_valid_service" time="0.001"><error type="exceptions.IOError" message="[Errno 2] No such file or directory: '/home/hasher/workspace/gladminds/src/../etc/data/template.json'"><![CDATA[Traceback (most recent call last):
  File "/usr/lib/python2.7/unittest/case.py", line 322, in run
    self.setUp()
  File "/home/hasher/workspace/gladminds/tests/integration/test_message.py", line 59, in setUp
    super(CustomerServiceTest, self).setUp()
  File "/home/hasher/workspace/gladminds/tests/integration/base_integration.py", line 15, in setUp
    message_templates = json.loads(open(file_path).read())
IOError: [Errno 2] No such file or directory: '/home/hasher/workspace/gladminds/src/../etc/data/template.json'
]]></error></testcase><testcase classname="integration.test_registration.TestDealerRegistration" name="test_adding_asc_and_chang_password" time="1.021"></testcase><testcase classname="integration.test_registration.TestDealerRegistration" name="test_new_dealer" time="0.422"></testcase><testcase classname="integration.test_save_form.TestSaveFormRegistration" name="test_asc_registration" time="0.014"></testcase><testcase classname="integration.test_save_form.TestSaveFormRegistration" name="test_fail_registration_mail" time="0.012"></testcase><testcase classname="integration.test_sqs.TestSQSTasks" name="test_send_on_product_purchase" time="0.009"><failure type="exceptions.AssertionError" message="Task Not Excecuted"><![CDATA[Traceback (most recent call last):
  File "/usr/lib/python2.7/unittest/case.py", line 331, in run
    testMethod()
  File "/home/hasher/workspace/gladminds/tests/integration/test_sqs.py", line 50, in test_send_on_product_purchase
    self.assertEqual(result.status_code, 200, "Task Not Excecuted")
  File "/usr/lib/python2.7/unittest/case.py", line 515, in assertEqual
    assertion_func(first, second, msg=msg)
  File "/usr/lib/python2.7/unittest/case.py", line 508, in _baseAssertEqual
    raise self.failureException(msg)
AssertionError: Task Not Excecuted
]]></failure></testcase><testcase classname="integration.test_temp_customer_registration.CustomerRegistrationFlowTest" name="test_register_customer" time="0.023"><failure type="exceptions.AssertionError" message="2 != 3&#10;-------------------- &gt;&gt; begin captured stdout &lt;&lt; ---------------------&#10;............ 302&#10;............. Vary: Cookie&#13;&#10;Content-Type: text/html; charset=utf-8&#13;&#10;Location: http://testserver/accounts/login/?next=/aftersell/register/customer&#13;&#10;&#13;&#10;&#10;&#10;--------------------- &gt;&gt; end captured stdout &lt;&lt; ----------------------"><![CDATA[  File "/usr/lib/python2.7/unittest/case.py", line 331, in run
    testMethod()
  File "/home/hasher/workspace/gladminds/tests/integration/test_temp_customer_registration.py", line 48, in test_register_customer
    self.assertEquals(2, 3)
  File "/usr/lib/python2.7/unittest/case.py", line 515, in assertEqual
    assertion_func(first, second, msg=msg)
  File "/usr/lib/python2.7/unittest/case.py", line 508, in _baseAssertEqual
    raise self.failureException(msg)
2 != 3
-------------------- >> begin captured stdout << ---------------------
............ 302
............. Vary: Cookie
Content-Type: text/html; charset=utf-8
Location: http://testserver/accounts/login/?next=/aftersell/register/customer



--------------------- >> end captured stdout << ----------------------]]></failure><system-out><![CDATA[............ 302
............. Vary: Cookie
Content-Type: text/html; charset=utf-8
Location: http://testserver/accounts/login/?next=/aftersell/register/customer


]]></system-out></testcase><testcase classname="unit.test_celery.TestCelery" name="test_send_sms" time="0.001"><error type="exceptions.IOError" message="[Errno 2] No such file or directory: '/home/hasher/workspace/gladminds/src/../etc/data/template.json'"><![CDATA[Traceback (most recent call last):
  File "/usr/lib/python2.7/unittest/case.py", line 322, in run
    self.setUp()
  File "/home/hasher/workspace/gladminds/tests/integration/base_integration.py", line 15, in setUp
    message_templates = json.loads(open(file_path).read())
IOError: [Errno 2] No such file or directory: '/home/hasher/workspace/gladminds/src/../etc/data/template.json'
]]></error></testcase><testcase classname="unit.test_celery.TestCelery" name="test_send_sms_fail" time="0.001"><error type="exceptions.IOError" message="[Errno 2] No such file or directory: '/home/hasher/workspace/gladminds/src/../etc/data/template.json'"><![CDATA[Traceback (most recent call last):
  File "/usr/lib/python2.7/unittest/case.py", line 322, in run
    self.setUp()
  File "/home/hasher/workspace/gladminds/tests/integration/base_integration.py", line 15, in setUp
    message_templates = json.loads(open(file_path).read())
IOError: [Errno 2] No such file or directory: '/home/hasher/workspace/gladminds/src/../etc/data/template.json'
]]></error></testcase><testcase classname="unit.test_celery.TestCronjobs" name="test_expire_service_coupon" time="0.210"></testcase><testcase classname="unit.test_celery.TestCronjobs" name="test_get_data_feed_log_detail" time="0.142"></testcase><testcase classname="unit.test_celery.TestTasks" name="test_tasks" time="0.003"><error type="exceptions.KeyError" message="None&#10;-------------------- &gt;&gt; begin captured logging &lt;&lt; --------------------&#10;gladminds: INFO: message addded&#10;--------------------- &gt;&gt; end captured logging &lt;&lt; ---------------------"><![CDATA[  File "/usr/lib/python2.7/unittest/case.py", line 331, in run
    testMethod()
  File "/home/hasher/workspace/gladminds/tests/unit/test_celery.py", line 101, in test_tasks
    sqs_tasks.send_registration_detail(message=self.message,phone_number=self.phone_number)
  File "/home/hasher/workspace/dev/lib/python2.7/site-packages/celery/local.py", line 167, in <lambda>
    __call__ = lambda x, *a, **kw: x._get_current_object()(*a, **kw)
  File "/home/hasher/workspace/dev/lib/python2.7/site-packages/celery/app/task.py", line 420, in __call__
    return self.run(*args, **kwargs)
  File "/home/hasher/workspace/gladminds/src/gladminds/sqs_tasks.py", line 33, in send_registration_detail
    exc=ex, countdown=10, kwargs=kwargs, max_retries=5)
  File "/home/hasher/workspace/dev/lib/python2.7/site-packages/celery/app/task.py", line 644, in retry
    maybe_reraise()  # raise orig stack if PyErr_Occurred
  File "/home/hasher/workspace/dev/lib/python2.7/site-packages/celery/utils/__init__.py", line 242, in maybe_reraise
    reraise(exc_info[0], exc_info[1], exc_info[2])
  File "/home/hasher/workspace/gladminds/src/gladminds/sqs_tasks.py", line 29, in send_registration_detail
    send_sms(**kwargs)
  File "/home/hasher/workspace/gladminds/src/gladminds/sqs_tasks.py", line 19, in send_sms
    sms_client_gateway = load_gateway(sms_client)
  File "/home/hasher/workspace/gladminds/src/gladminds/dao/smsclient.py", line 11, in load_gateway
    client = settings.SMS_CLIENT_DETAIL[sms_client]
'None\n-------------------- >> begin captured logging << --------------------\ngladminds: INFO: message addded\n--------------------- >> end captured logging << ---------------------']]></error></testcase><testcase classname="unit.test_csvfeed.CSVFeedTest" name="test_brandproducttypefeed" time="0.025"></testcase><testcase classname="unit.test_csvfeed.CSVFeedTest" name="test_import_duplicate_feed" time="0.033"></testcase><testcase classname="unit.test_resource.GladmindsResourcesTest" name="test_close_coupon" time="0.001"><error type="exceptions.IOError" message="[Errno 2] No such file or directory: '/home/hasher/workspace/gladminds/src/../etc/data/template.json'"><![CDATA[Traceback (most recent call last):
  File "/usr/lib/python2.7/unittest/case.py", line 322, in run
    self.setUp()
  File "/home/hasher/workspace/gladminds/tests/unit/test_resource.py", line 14, in setUp
    super(GladmindsResourcesTest, self).setUp()
  File "/home/hasher/workspace/gladminds/tests/integration/base_integration.py", line 15, in setUp
    message_templates = json.loads(open(file_path).read())
IOError: [Errno 2] No such file or directory: '/home/hasher/workspace/gladminds/src/../etc/data/template.json'
]]></error></testcase><testcase classname="unit.test_resource.GladmindsResourcesTest" name="test_coupon_initiators" time="0.001"><error type="exceptions.IOError" message="[Errno 2] No such file or directory: '/home/hasher/workspace/gladminds/src/../etc/data/template.json'"><![CDATA[Traceback (most recent call last):
  File "/usr/lib/python2.7/unittest/case.py", line 322, in run
    self.setUp()
  File "/home/hasher/workspace/gladminds/tests/unit/test_resource.py", line 14, in setUp
    super(GladmindsResourcesTest, self).setUp()
  File "/home/hasher/workspace/gladminds/tests/integration/base_integration.py", line 15, in setUp
    message_templates = json.loads(open(file_path).read())
IOError: [Errno 2] No such file or directory: '/home/hasher/workspace/gladminds/src/../etc/data/template.json'
]]></error></testcase><testcase classname="unit.test_resource.GladmindsResourcesTest" name="test_customer_service_detail" time="0.001"><error type="exceptions.IOError" message="[Errno 2] No such file or directory: '/home/hasher/workspace/gladminds/src/../etc/data/template.json'"><![CDATA[Traceback (most recent call last):
  File "/usr/lib/python2.7/unittest/case.py", line 322, in run
    self.setUp()
  File "/home/hasher/workspace/gladminds/tests/unit/test_resource.py", line 14, in setUp
    super(GladmindsResourcesTest, self).setUp()
  File "/home/hasher/workspace/gladminds/tests/integration/base_integration.py", line 15, in setUp
    message_templates = json.loads(open(file_path).read())
IOError: [Errno 2] No such file or directory: '/home/hasher/workspace/gladminds/src/../etc/data/template.json'
]]></error></testcase><testcase classname="unit.test_resource.GladmindsResourcesTest" name="test_dispatch_gladminds" time="0.001"><error type="exceptions.IOError" message="[Errno 2] No such file or directory: '/home/hasher/workspace/gladminds/src/../etc/data/template.json'"><![CDATA[Traceback (most recent call last):
  File "/usr/lib/python2.7/unittest/case.py", line 322, in run
    self.setUp()
  File "/home/hasher/workspace/gladminds/tests/unit/test_resource.py", line 14, in setUp
    super(GladmindsResourcesTest, self).setUp()
  File "/home/hasher/workspace/gladminds/tests/integration/base_integration.py", line 15, in setUp
    message_templates = json.loads(open(file_path).read())
IOError: [Errno 2] No such file or directory: '/home/hasher/workspace/gladminds/src/../etc/data/template.json'
]]></error></testcase><testcase classname="unit.test_resource.GladmindsResourcesTest" name="test_expire_or_close_less_kms_coupon" time="0.001"><error type="exceptions.IOError" message="[Errno 2] No such file or directory: '/home/hasher/workspace/gladminds/src/../etc/data/template.json'"><![CDATA[Traceback (most recent call last):
  File "/usr/lib/python2.7/unittest/case.py", line 322, in run
    self.setUp()
  File "/home/hasher/workspace/gladminds/tests/unit/test_resource.py", line 14, in setUp
    super(GladmindsResourcesTest, self).setUp()
  File "/home/hasher/workspace/gladminds/tests/integration/base_integration.py", line 15, in setUp
    message_templates = json.loads(open(file_path).read())
IOError: [Errno 2] No such file or directory: '/home/hasher/workspace/gladminds/src/../etc/data/template.json'
]]></error></testcase><testcase classname="unit.test_resource.GladmindsResourcesTest" name="test_format_message" time="0.001"><error type="exceptions.IOError" message="[Errno 2] No such file or directory: '/home/hasher/workspace/gladminds/src/../etc/data/template.json'"><![CDATA[Traceback (most recent call last):
  File "/usr/lib/python2.7/unittest/case.py", line 322, in run
    self.setUp()
  File "/home/hasher/workspace/gladminds/tests/unit/test_resource.py", line 14, in setUp
    super(GladmindsResourcesTest, self).setUp()
  File "/home/hasher/workspace/gladminds/tests/integration/base_integration.py", line 15, in setUp
    message_templates = json.loads(open(file_path).read())
IOError: [Errno 2] No such file or directory: '/home/hasher/workspace/gladminds/src/../etc/data/template.json'
]]></error></testcase><testcase classname="unit.test_resource.GladmindsResourcesTest" name="test_inprogress_coupon" time="0.001"><error type="exceptions.IOError" message="[Errno 2] No such file or directory: '/home/hasher/workspace/gladminds/src/../etc/data/template.json'"><![CDATA[Traceback (most recent call last):
  File "/usr/lib/python2.7/unittest/case.py", line 322, in run
    self.setUp()
  File "/home/hasher/workspace/gladminds/tests/unit/test_resource.py", line 14, in setUp
    super(GladmindsResourcesTest, self).setUp()
  File "/home/hasher/workspace/gladminds/tests/integration/base_integration.py", line 15, in setUp
    message_templates = json.loads(open(file_path).read())
IOError: [Errno 2] No such file or directory: '/home/hasher/workspace/gladminds/src/../etc/data/template.json'
]]></error></testcase><testcase classname="unit.test_resource.GladmindsResourcesTest" name="test_is_valid_data" time="0.001"><error type="exceptions.IOError" message="[Errno 2] No such file or directory: '/home/hasher/workspace/gladminds/src/../etc/data/template.json'"><![CDATA[Traceback (most recent call last):
  File "/usr/lib/python2.7/unittest/case.py", line 322, in run
    self.setUp()
  File "/home/hasher/workspace/gladminds/tests/unit/test_resource.py", line 14, in setUp
    super(GladmindsResourcesTest, self).setUp()
  File "/home/hasher/workspace/gladminds/tests/integration/base_integration.py", line 15, in setUp
    message_templates = json.loads(open(file_path).read())
IOError: [Errno 2] No such file or directory: '/home/hasher/workspace/gladminds/src/../etc/data/template.json'
]]></error></testcase><testcase classname="unit.test_resource.GladmindsResourcesTest" name="test_no_available_coupons" time="0.001"><error type="exceptions.IOError" message="[Errno 2] No such file or directory: '/home/hasher/workspace/gladminds/src/../etc/data/template.json'"><![CDATA[Traceback (most recent call last):
  File "/usr/lib/python2.7/unittest/case.py", line 322, in run
    self.setUp()
  File "/home/hasher/workspace/gladminds/tests/unit/test_resource.py", line 14, in setUp
    super(GladmindsResourcesTest, self).setUp()
  File "/home/hasher/workspace/gladminds/tests/integration/base_integration.py", line 15, in setUp
    message_templates = json.loads(open(file_path).read())
IOError: [Errno 2] No such file or directory: '/home/hasher/workspace/gladminds/src/../etc/data/template.json'
]]></error></testcase><testcase classname="unit.test_resource.GladmindsResourcesTest" name="test_register_customer" time="0.001"><error type="exceptions.IOError" message="[Errno 2] No such file or directory: '/home/hasher/workspace/gladminds/src/../etc/data/template.json'"><![CDATA[Traceback (most recent call last):
  File "/usr/lib/python2.7/unittest/case.py", line 322, in run
    self.setUp()
  File "/home/hasher/workspace/gladminds/tests/unit/test_resource.py", line 14, in setUp
    super(GladmindsResourcesTest, self).setUp()
  File "/home/hasher/workspace/gladminds/tests/integration/base_integration.py", line 15, in setUp
    message_templates = json.loads(open(file_path).read())
IOError: [Errno 2] No such file or directory: '/home/hasher/workspace/gladminds/src/../etc/data/template.json'
]]></error></testcase><testcase classname="unit.test_smsparser.SmsParserTest" name="test_invalid_keyword" time="0.001"><error type="exceptions.IOError" message="[Errno 2] No such file or directory: '/home/hasher/workspace/gladminds/src/../etc/data/template.json'"><![CDATA[Traceback (most recent call last):
  File "/usr/lib/python2.7/unittest/case.py", line 322, in run
    self.setUp()
  File "/home/hasher/workspace/gladminds/tests/unit/test_smsparser.py", line 16, in setUp
    message_templates = json.loads(open(file_path).read())
IOError: [Errno 2] No such file or directory: '/home/hasher/workspace/gladminds/src/../etc/data/template.json'
]]></error></testcase><testcase classname="unit.test_smsparser.SmsParserTest" name="test_invalid_keyword_2" time="0.001"><error type="exceptions.IOError" message="[Errno 2] No such file or directory: '/home/hasher/workspace/gladminds/src/../etc/data/template.json'"><![CDATA[Traceback (most recent call last):
  File "/usr/lib/python2.7/unittest/case.py", line 322, in run
    self.setUp()
  File "/home/hasher/workspace/gladminds/tests/unit/test_smsparser.py", line 16, in setUp
    message_templates = json.loads(open(file_path).read())
IOError: [Errno 2] No such file or directory: '/home/hasher/workspace/gladminds/src/../etc/data/template.json'
]]></error></testcase><testcase classname="unit.test_smsparser.SmsParserTest" name="test_invalid_message_format" time="0.001"><error type="exceptions.IOError" message="[Errno 2] No such file or directory: '/home/hasher/workspace/gladminds/src/../etc/data/template.json'"><![CDATA[Traceback (most recent call last):
  File "/usr/lib/python2.7/unittest/case.py", line 322, in run
    self.setUp()
  File "/home/hasher/workspace/gladminds/tests/unit/test_smsparser.py", line 16, in setUp
    message_templates = json.loads(open(file_path).read())
IOError: [Errno 2] No such file or directory: '/home/hasher/workspace/gladminds/src/../etc/data/template.json'
]]></error></testcase><testcase classname="unit.test_smsparser.SmsParserTest" name="test_sms_parse" time="0.001"><error type="exceptions.IOError" message="[Errno 2] No such file or directory: '/home/hasher/workspace/gladminds/src/../etc/data/template.json'"><![CDATA[Traceback (most recent call last):
  File "/usr/lib/python2.7/unittest/case.py", line 322, in run
    self.setUp()
  File "/home/hasher/workspace/gladminds/tests/unit/test_smsparser.py", line 16, in setUp
    message_templates = json.loads(open(file_path).read())
IOError: [Errno 2] No such file or directory: '/home/hasher/workspace/gladminds/src/../etc/data/template.json'
]]></error></testcase><testcase classname="unit.test_unit.TestAssertWorks" name="test_assert_equals" time="0.001"></testcase><testcase classname="unit.test_unit.TestAssertWorks" name="test_assert_true" time="0.000"></testcase><testcase classname="unit.test_unit.TestFeedLogWithRemark" name="test_remarks" time="0.852"><error type="exceptions.TypeError" message="expected string or buffer&#10;-------------------- &gt;&gt; begin captured logging &lt;&lt; --------------------&#10;gladminds: ERROR: DealerService: DealerModel(ACTIVE_FLAG=u'Y', TIMESTAMP=u'2014-04-01000000', SER_ADV_ID=u'HISA001', ADDRESS=u'Marathalli', SER_ADV_NAME=u'TestUser01', KUNNR=u'HIDealer001')  Error on Validating 'NoneType' object has no attribute '__getitem__'&#10;gladminds: INFO: New dealer Registration with id - HIDealer001&#10;gladminds: INFO: [Exception: new_ registration]: Group matching query does not exist.&#10;gladminds: INFO: [Exception: new_ registration]: User matching query does not exist.&#10;gladminds: INFO: dealer HIDealer001 registered successfully&#10;gladminds: INFO: [Exception:  DealerAndServiceAdvisorFeed_sa]: ServiceAdvisor matching query does not exist.&#10;gladminds: INFO: New SA Registration with id - HISA002&#10;gladminds: INFO: [Exception: new_ registration]: Group matching query does not exist.&#10;gladminds: INFO: [Exception: new_ registration]: User matching query does not exist.&#10;gladminds: INFO: SA HISA002 registered successfully&#10;py.warnings: WARNING: /home/hasher/workspace/gladminds/eggs/Django-1.6.4-py2.7.egg/django/db/models/fields/__init__.py:903: RuntimeWarning: DateTimeField DataFeedLog.timestamp received a naive datetime (2014-10-13 12:22:45.422150) while time zone support is active.&#10;  RuntimeWarning)&#10;&#10;--------------------- &gt;&gt; end captured logging &lt;&lt; ---------------------"><![CDATA[  File "/usr/lib/python2.7/unittest/case.py", line 331, in run
    testMethod()
  File "/home/hasher/workspace/gladminds/tests/unit/test_unit.py", line 91, in test_remarks
    remark = json.loads(feed_logs_obj[0].remarks)
  File "/usr/lib/python2.7/json/__init__.py", line 338, in loads
    return _default_decoder.decode(s)
  File "/usr/lib/python2.7/json/decoder.py", line 366, in decode
    obj, end = self.raw_decode(s, idx=_w(s, 0).end())
"expected string or buffer\n-------------------- >> begin captured logging << --------------------\ngladminds: ERROR: DealerService: DealerModel(ACTIVE_FLAG=u'Y', TIMESTAMP=u'2014-04-01000000', SER_ADV_ID=u'HISA001', ADDRESS=u'Marathalli', SER_ADV_NAME=u'TestUser01', KUNNR=u'HIDealer001')  Error on Validating 'NoneType' object has no attribute '__getitem__'\ngladminds: INFO: New dealer Registration with id - HIDealer001\ngladminds: INFO: [Exception: new_ registration]: Group matching query does not exist.\ngladminds: INFO: [Exception: new_ registration]: User matching query does not exist.\ngladminds: INFO: dealer HIDealer001 registered successfully\ngladminds: INFO: [Exception:  DealerAndServiceAdvisorFeed_sa]: ServiceAdvisor matching query does not exist.\ngladminds: INFO: New SA Registration with id - HISA002\ngladminds: INFO: [Exception: new_ registration]: Group matching query does not exist.\ngladminds: INFO: [Exception: new_ registration]: User matching query does not exist.\ngladminds: INFO: SA HISA002 registered successfully\npy.warnings: WARNING: /home/hasher/workspace/gladminds/eggs/Django-1.6.4-py2.7.egg/django/db/models/fields/__init__.py:903: RuntimeWarning: DateTimeField DataFeedLog.timestamp received a naive datetime (2014-10-13 12:22:45.422150) while time zone support is active.\n  RuntimeWarning)\n\n--------------------- >> end captured logging << ---------------------"]]></error></testcase><testcase classname="unit.test_unit.TestUtils" name="test_get_sa_list" time="0.257"><error type="exceptions.IndexError" message="list index out of range&#10;-------------------- &gt;&gt; begin captured logging &lt;&lt; --------------------&#10;py.warnings: WARNING: /home/hasher/workspace/gladminds/eggs/Django-1.6.4-py2.7.egg/django/db/models/fields/__init__.py:903: RuntimeWarning: DateTimeField ProductData.product_purchase_date received a naive datetime (2014-10-13 12:22:45.438843) while time zone support is active.&#10;  RuntimeWarning)&#10;&#10;gladminds: INFO: triggered update_coupon_data&#10;gladminds: INFO: [Exception]: Signal-In Update Coupon Data MessageTemplate matching query does not exist.&#10;py.warnings: WARNING: /home/hasher/workspace/gladminds/eggs/Django-1.6.4-py2.7.egg/django/db/models/fields/__init__.py:903: RuntimeWarning: DateTimeField CouponData.mark_expired_on received a naive datetime (2014-10-11 12:22:45.458192) while time zone support is active.&#10;  RuntimeWarning)&#10;&#10;py.warnings: WARNING: /home/hasher/workspace/gladminds/eggs/Django-1.6.4-py2.7.egg/django/db/models/fields/__init__.py:903: RuntimeWarning: DateTimeField CouponData.actual_service_date received a naive datetime (2014-09-23 12:22:45.458248) while time zone support is active.&#10;  RuntimeWarning)&#10;&#10;py.warnings: WARNING: /home/hasher/workspace/gladminds/eggs/Django-1.6.4-py2.7.egg/django/db/models/fields/__init__.py:903: RuntimeWarning: DateTimeField CouponData.extended_date received a naive datetime (2014-10-11 12:22:45.458260) while time zone support is active.&#10;  RuntimeWarning)&#10;&#10;py.warnings: WARNING: /home/hasher/workspace/gladminds/eggs/Django-1.6.4-py2.7.egg/django/db/models/fields/__init__.py:903: RuntimeWarning: DateTimeField RegisteredASC.registration_date received a naive datetime (2014-10-13 12:22:22.076021) while time zone support is active.&#10;  RuntimeWarning)&#10;&#10;--------------------- &gt;&gt; end captured logging &lt;&lt; ---------------------"><![CDATA[  File "/usr/lib/python2.7/unittest/case.py", line 331, in run
    testMethod()
  File "/home/hasher/workspace/gladminds/tests/unit/test_unit.py", line 55, in test_get_sa_list
    sa_list = get_sa_list(request)
  File "/home/hasher/workspace/gladminds/src/gladminds/utils.py", line 123, in get_sa_list
    dealer_id=user)[0]
  File "/home/hasher/workspace/gladminds/eggs/Django-1.6.4-py2.7.egg/django/db/models/query.py", line 132, in __getitem__
    return list(qs)[0]
'list index out of range\n-------------------- >> begin captured logging << --------------------\npy.warnings: WARNING: /home/hasher/workspace/gladminds/eggs/Django-1.6.4-py2.7.egg/django/db/models/fields/__init__.py:903: RuntimeWarning: DateTimeField ProductData.product_purchase_date received a naive datetime (2014-10-13 12:22:45.438843) while time zone support is active.\n  RuntimeWarning)\n\ngladminds: INFO: triggered update_coupon_data\ngladminds: INFO: [Exception]: Signal-In Update Coupon Data MessageTemplate matching query does not exist.\npy.warnings: WARNING: /home/hasher/workspace/gladminds/eggs/Django-1.6.4-py2.7.egg/django/db/models/fields/__init__.py:903: RuntimeWarning: DateTimeField CouponData.mark_expired_on received a naive datetime (2014-10-11 12:22:45.458192) while time zone support is active.\n  RuntimeWarning)\n\npy.warnings: WARNING: /home/hasher/workspace/gladminds/eggs/Django-1.6.4-py2.7.egg/django/db/models/fields/__init__.py:903: RuntimeWarning: DateTimeField CouponData.actual_service_date received a naive datetime (2014-09-23 12:22:45.458248) while time zone support is active.\n  RuntimeWarning)\n\npy.warnings: WARNING: /home/hasher/workspace/gladminds/eggs/Django-1.6.4-py2.7.egg/django/db/models/fields/__init__.py:903: RuntimeWarning: DateTimeField CouponData.extended_date received a naive datetime (2014-10-11 12:22:45.458260) while time zone support is active.\n  RuntimeWarning)\n\npy.warnings: WARNING: /home/hasher/workspace/gladminds/eggs/Django-1.6.4-py2.7.egg/django/db/models/fields/__init__.py:903: RuntimeWarning: DateTimeField RegisteredASC.registration_date received a naive datetime (2014-10-13 12:22:22.076021) while time zone support is active.\n  RuntimeWarning)\n\n--------------------- >> end captured logging << ---------------------']]></error></testcase><testcase classname="unit.test_unit.TestUtils" name="test_otp" time="0.288"></testcase><testcase classname="nose.failure.Failure" name="runTest" time="0.000"><error type="exceptions.ImportError" message="No module named core"><![CDATA[Traceback (most recent call last):
  File "/usr/lib/python2.7/unittest/case.py", line 331, in run
    testMethod()
  File "/home/hasher/workspace/gladminds/eggs/nose-1.3.4-py2.7.egg/nose/loader.py", line 414, in loadTestsFromName
    addr.filename, addr.module)
  File "/home/hasher/workspace/gladminds/eggs/nose-1.3.4-py2.7.egg/nose/importer.py", line 47, in importFromPath
    return self.importFromDir(dir_path, fqname)
  File "/home/hasher/workspace/gladminds/eggs/nose-1.3.4-py2.7.egg/nose/importer.py", line 94, in importFromDir
    mod = load_module(part_fqname, fh, filename, desc)
  File "/home/hasher/workspace/gladminds/tests/integration/test_customer_registration.py", line 1, in <module>
    from gladminds.core import taskmanager, feed, export_file, exportfeed
ImportError: No module named core
]]></error></testcase></testsuite>